<?xml version="1.0" encoding="utf-8"?>
<!-- This URDF was automatically created by SolidWorks to URDF Exporter! Originally created by Stephen Brawner (brawner@gmail.com) 
     Commit Version: 1.5.0-0-g9aa0fdb  Build Version: 1.5.7004.21443
     For more information, please see http://wiki.ros.org/sw_urdf_exporter -->
<robot
  name="car_model_t1">
  <link
    name="base_link">
    <inertial>
      <origin
        xyz="0.0060229 0.011392 0.15352"
        rpy="0 0 0" />
      <mass
        value="0.18739" />
      <inertia
        ixx="0.00035976"
        ixy="4.5411E-20"
        ixz="-1.1207E-21"
        iyy="0.00018258"
        iyz="2.7143E-08"
        izz="0.00047754" />
    </inertial>
    <visual>
      <origin
        xyz="0 0 0"
        rpy="0 0 0" />
      <geometry>
        <mesh
          filename="package://car_model_t1/meshes/base_link.STL" />
      </geometry>
      <material
        name="">
        <color
          rgba="1 0.40784 0.39216 1" />
      </material>
    </visual>
    <collision>
      <origin
        xyz="0 0 0"
        rpy="0 0 0" />
      <geometry>
        <mesh
          filename="package://car_model_t1/meshes/base_link.STL" />
      </geometry>
    </collision>
  </link>
  <link
    name="left_wheel">
    <inertial>
      <origin
        xyz="0 -0.00032962 0"
        rpy="0 0 0" />
      <mass
        value="0.013351" />
      <inertia
        ixx="1.4054E-06"
        ixy="3.7516E-23"
        ixz="3.2612E-24"
        iyy="2.3499E-06"
        iyz="-3.6115E-23"
        izz="1.4054E-06" />
    </inertial>
    <visual>
      <origin
        xyz="0 0 0"
        rpy="0 0 0" />
      <geometry>
        <mesh
          filename="package://car_model_t1/meshes/left_wheel.STL" />
      </geometry>
      <material
        name="">
        <color
          rgba="0.79608 0.82353 0.93725 1" />
      </material>
    </visual>
    <collision>
      <origin
        xyz="0 0 0"
        rpy="0 0 0" />
      <geometry>
        <mesh
          filename="package://car_model_t1/meshes/left_wheel.STL" />
      </geometry>
    </collision>
  </link>
  <joint
    name="base_to_left"
    type="continuous">
    <origin
      xyz="0.048523 0.011386 0.142"
      rpy="0 0 -1.5708" />
    <parent
      link="base_link" />
    <child
      link="left_wheel" />
    <axis
      xyz="0 -1 0" />
    <safety_controller
      k_velocity="0" />
  </joint>
  <link
    name="right_wheel">
    <inertial>
      <origin
        xyz="1.7347E-18 0.00033063 0"
        rpy="0 0 0" />
      <mass
        value="0.013453" />
      <inertia
        ixx="1.4184E-06"
        ixy="-3.6757E-23"
        ixz="-1.1017E-23"
        iyy="2.3664E-06"
        iyz="-3.8007E-23"
        izz="1.4184E-06" />
    </inertial>
    <visual>
      <origin
        xyz="0 0 0"
        rpy="0 0 0" />
      <geometry>
        <mesh
          filename="package://car_model_t1/meshes/right_wheel.STL" />
      </geometry>
      <material
        name="">
        <color
          rgba="0.79608 0.82353 0.93725 1" />
      </material>
    </visual>
    <collision>
      <origin
        xyz="0 0 0"
        rpy="0 0 0" />
      <geometry>
        <mesh
          filename="package://car_model_t1/meshes/right_wheel.STL" />
      </geometry>
    </collision>
  </link>
  <joint
    name="base_to_right"
    type="continuous">
    <origin
      xyz="-0.036527 0.011386 0.142"
      rpy="0 0 -1.5708" />
    <parent
      link="base_link" />
    <child
      link="right_wheel" />
    <axis
      xyz="0 -1 0" />
    <safety_controller
      k_velocity="0" />
  </joint>
  <link
    name="front_wheel">
    <inertial>
      <origin
        xyz="0 8.6736E-19 0"
        rpy="0 0 0" />
      <mass
        value="0.00059041" />
      <inertia
        ixx="7.8748E-09"
        ixy="2.9696E-24"
        ixz="-2.1139E-26"
        iyy="1.4243E-08"
        iyz="-2.6839E-25"
        izz="7.8748E-09" />
    </inertial>
    <visual>
      <origin
        xyz="0 0 0"
        rpy="0 0 0" />
      <geometry>
        <mesh
          filename="package://car_model_t1/meshes/front_wheel.STL" />
      </geometry>
      <material
        name="">
        <color
          rgba="0.41176 0.41176 0.41176 1" />
      </material>
    </visual>
    <collision>
      <origin
        xyz="0 0 0"
        rpy="0 0 0" />
      <geometry>
        <mesh
          filename="package://car_model_t1/meshes/front_wheel.STL" />
      </geometry>
    </collision>
  </link>
  <joint
    name="base_to_front"
    type="continuous">
    <origin
      xyz="0.0060229 -0.047114 0.131"
      rpy="0 0 -1.5708" />
    <parent
      link="base_link" />
    <child
      link="front_wheel" />
    <axis
      xyz="0 0 -1" />
    <safety_controller
      k_velocity="0" />
  </joint>
  <link
    name="back_wheel">
    <inertial>
      <origin
        xyz="0 0 0"
        rpy="0 0 0" />
      <mass
        value="0.00059041" />
      <inertia
        ixx="7.8748E-09"
        ixy="-1.0069E-24"
        ixz="-3.543E-24"
        iyy="1.4243E-08"
        iyz="1.3457E-25"
        izz="7.8748E-09" />
    </inertial>
    <visual>
      <origin
        xyz="0 0 0"
        rpy="0 0 0" />
      <geometry>
        <mesh
          filename="package://car_model_t1/meshes/back_wheel.STL" />
      </geometry>
      <material
        name="">
        <color
          rgba="0.41176 0.41176 0.41176 1" />
      </material>
    </visual>
    <collision>
      <origin
        xyz="0 0 0"
        rpy="0 0 0" />
      <geometry>
        <mesh
          filename="package://car_model_t1/meshes/back_wheel.STL" />
      </geometry>
    </collision>
  </link>
  <joint
    name="base_to_back"
    type="continuous">
    <origin
      xyz="0.0060229 0.082886 0.131"
      rpy="0 0 -1.5708" />
    <parent
      link="base_link" />
    <child
      link="back_wheel" />
    <axis
      xyz="0 0 -1" />
    <safety_controller
      k_velocity="0" />
  </joint>
</robot>