<?xml version="1.0" encoding="utf-8"?>
<!-- This URDF was automatically created by SolidWorks to URDF Exporter! Originally created by Stephen Brawner (brawner@gmail.com) 
     Commit Version: 1.5.0-0-g9aa0fdb  Build Version: 1.5.7004.21443
     For more information, please see http://wiki.ros.org/sw_urdf_exporter -->
<robot
  name="car_model_t4">
  <link
    name="base_link">
    <inertial>
      <origin
        xyz="-6.4312E-06 -4.3368E-18 0.014523"
        rpy="0 0 0" />
      <mass
        value="0.18739" />
      <inertia
        ixx="0.00018258"
        ixy="-4.2641E-20"
        ixz="-2.7143E-08"
        iyy="0.00035976"
        iyz="1.3591E-22"
        izz="0.00047754" />
    </inertial>
    <visual>
      <origin
        xyz="0 0 0"
        rpy="0 0 0" />
      <geometry>
        <mesh
          filename="package://car_model_t4/meshes/base_link.STL" />
      </geometry>
      <material
        name="">
        <color
          rgba="1 0.40784 0.39216 1" />
      </material>
    </visual>
    <collision>
      <origin
        xyz="0 0 0"
        rpy="0 0 0" />
      <geometry>
        <mesh
          filename="package://car_model_t4/meshes/base_link.STL" />
      </geometry>
    </collision>
  </link>
  <link
    name="left_wheel">
    <inertial>
      <origin
        xyz="0 -0.00032962 0"
        rpy="0 0 0" />
      <mass
        value="0.013351" />
      <inertia
        ixx="1.4054E-06"
        ixy="3.7502E-23"
        ixz="3.2627E-24"
        iyy="2.3499E-06"
        iyz="-3.6116E-23"
        izz="1.4054E-06" />
    </inertial>
    <visual>
      <origin
        xyz="0 0 0"
        rpy="0 0 0" />
      <geometry>
        <mesh
          filename="package://car_model_t4/meshes/left_wheel.STL" />
      </geometry>
      <material
        name="">
        <color
          rgba="0.79608 0.82353 0.93725 1" />
      </material>
    </visual>
    <collision>
      <origin
        xyz="0 0 0"
        rpy="0 0 0" />
      <geometry>
        <mesh
          filename="package://car_model_t4/meshes/left_wheel.STL" />
      </geometry>
    </collision>
  </link>

  <joint
    name="base_to_left"
    type="continuous">
    <origin
      xyz="0 0.0425 0.003"
      rpy="0 0 0" />
    <parent
      link="base_link" />
    <child
      link="left_wheel" />
    <axis
      xyz="0 -1 0" />
    <safety_controller
      k_velocity="0" />
  </joint>
  <link
    name="right_wheel">
    <inertial>
      <origin
        xyz="0 0.00033063 -2.7756E-17"
        rpy="0 0 0" />
      <mass
        value="0.013453" />
      <inertia
        ixx="1.4184E-06"
        ixy="-3.676E-23"
        ixz="-1.1014E-23"
        iyy="2.3664E-06"
        iyz="-3.8005E-23"
        izz="1.4184E-06" />
    </inertial>
    <visual>
      <origin
        xyz="0 0 0"
        rpy="0 0 0" />
      <geometry>
        <mesh
          filename="package://car_model_t4/meshes/right_wheel.STL" />
      </geometry>
      <material
        name="">
        <color
          rgba="0.79608 0.82353 0.93725 1" />
      </material>
    </visual>
    <collision>
      <origin
        xyz="0 0 0"
        rpy="0 0 0" />
      <geometry>
        <mesh
          filename="package://car_model_t4/meshes/right_wheel.STL" />
      </geometry>
    </collision>
  </link>
  <joint
    name="base_to_right"
    type="continuous">
    <origin
      xyz="0 -0.04255 0.003"
      rpy="0 0 0" />
    <parent
      link="base_link" />
    <child
      link="right_wheel" />
    <axis
      xyz="0 -1 0" />
    <safety_controller
      k_velocity="0" />
  </joint>
  <link
    name="front_wheel">
    <inertial>
      <origin
        xyz="0 8.6736E-19 0"
        rpy="0 0 0" />
      <mass
        value="0.00059041" />
      <inertia
        ixx="7.8748E-09"
        ixy="2.9696E-24"
        ixz="-2.1139E-26"
        iyy="1.4243E-08"
        iyz="-2.6839E-25"
        izz="7.8748E-09" />
    </inertial>
    <visual>
      <origin
        xyz="0 0 0"
        rpy="0 0 0" />
      <geometry>
        <mesh
          filename="package://car_model_t4/meshes/front_wheel.STL" />
      </geometry>
      <material
        name="">
        <color
          rgba="0.41176 0.41176 0.41176 1" />
      </material>
    </visual>
    <collision>
      <origin
        xyz="0 0 0"
        rpy="0 0 0" />
      <geometry>
        <mesh
          filename="package://car_model_t4/meshes/front_wheel.STL" />
      </geometry>
    </collision>
  </link>
  <joint
    name="base_to_front"
    type="continuous">
    <origin
      xyz="0.0585 0 -0.008"
      rpy="0 0 0" />
    <parent
      link="base_link" />
    <child
      link="front_wheel" />
    <axis
      xyz="0 -1 0" />
    <safety_controller
      k_velocity="0" />
  </joint>
  <link
    name="back_wheel">
    <inertial>
      <origin
        xyz="0 0 0"
        rpy="0 0 0" />
      <mass
        value="0.00059041" />
      <inertia
        ixx="7.8748E-09"
        ixy="-1.0069E-24"
        ixz="-3.543E-24"
        iyy="1.4243E-08"
        iyz="1.3457E-25"
        izz="7.8748E-09" />
    </inertial>
    <visual>
      <origin
        xyz="0 0 0"
        rpy="0 0 0" />
      <geometry>
        <mesh
          filename="package://car_model_t4/meshes/back_wheel.STL" />
      </geometry>
      <material
        name="">
        <color
          rgba="0.41176 0.41176 0.41176 1" />
      </material>
    </visual>
    <collision>
      <origin
        xyz="0 0 0"
        rpy="0 0 0" />
      <geometry>
        <mesh
          filename="package://car_model_t4/meshes/back_wheel.STL" />
      </geometry>
    </collision>
  </link>
  <joint
    name="base_to_back"
    type="continuous">
    <origin
      xyz="-0.0715 0 -0.008"
      rpy="0 0 0" />
    <parent
      link="base_link" />
    <child
      link="back_wheel" />
    <axis
      xyz="0 -1 0" />
    <safety_controller
      k_velocity="0" />
  </joint>

  <!-- controller -->
  <gazebo>
      <plugin name="differential_drive_controller" filename="libgazebo_ros_diff_drive.so">
          <alwaysOn>true</alwaysOn>
          <robotNamespace>/</robotNamespace>
          <rosDebugLevel>Debug</rosDebugLevel>
          <publishWheelTF>true</publishWheelTF>                
          <publishTf>1</publishTf>
          <publishWheelJointState>true</publishWheelJointState>
          <updateRate>100.0</updateRate>
          <legacyMode>true</legacyMode>
          <leftJoint>base_to_left</leftJoint>
          <rightJoint>base_to_right</rightJoint>
          <wheelSeparation>0.1</wheelSeparation>
          <wheelDiameter>0.036</wheelDiameter>
          <broadcastTF>1</broadcastTF>
          <wheelTorque>30</wheelTorque>
          <wheelAcceleration>1.8</wheelAcceleration>
          <commandTopic>cmd_vel</commandTopic>
          <odometryFrame>odom</odometryFrame> 
          <odometryTopic>odom</odometryTopic> 
          <robotBaseFrame>base_link</robotBaseFrame>
      </plugin>
  </gazebo> 

  <gazebo reference="left_wheel">
    <mu>0.8</mu>
    <mu2>0.8</mu2>
    <kp>100000000.0</kp>
    <kd>10000.0</kd>    
  </gazebo>
    <gazebo reference="right_wheel">
    <mu>0.8</mu>
    <mu2>0.8</mu2>
    <kp>100000000.0</kp>
    <kd>10000.0</kd>    
  </gazebo>
    <gazebo reference="front_wheel">
    <mu>0.1</mu>
    <mu2>0.1</mu2>
    <kp>100000000.0</kp>
    <kd>10000.0</kd>    
  </gazebo>
    <gazebo reference="back_wheel">
    <mu>0.1</mu>
    <mu2>0.1</mu2>
    <kp>100000000.0</kp>
    <kd>10000.0</kd>    
  </gazebo>
</robot>