<?xml version="1.0" encoding="utf-8"?>
<!-- This URDF was automatically created by SolidWorks to URDF Exporter! Originally created by Stephen Brawner (brawner@gmail.com) 
     Commit Version: 1.5.0-0-g9aa0fdb  Build Version: 1.5.7004.21443
     For more information, please see http://wiki.ros.org/sw_urdf_exporter -->
<robot
  name="car_model_t3">
  <link
    name="base_link">
    <inertial>
      <origin
        xyz="-6.4312E-06 5.2042E-18 0.014523"
        rpy="0 0 0" />
      <mass
        value="0.18739" />
      <inertia
        ixx="0.00018258"
        ixy="-5.4904E-20"
        ixz="-2.7143E-08"
        iyy="0.00035976"
        iyz="-2.4274E-21"
        izz="0.00047754" />
    </inertial>
    <visual>
      <origin
        xyz="0 0 0"
        rpy="0 0 0" />
      <geometry>
        <mesh
          filename="package://car_model_t3/meshes/base_link.STL" />
      </geometry>
      <material
        name="">
        <color
          rgba="1 0.40784 0.39216 1" />
      </material>
    </visual>
    <collision>
      <origin
        xyz="0 0 0"
        rpy="0 0 0" />
      <geometry>
        <mesh
          filename="package://car_model_t3/meshes/base_link.STL" />
      </geometry>
    </collision>
  </link>
  <link
    name="left_wheel">
    <inertial>
      <origin
        xyz="0 -0.000329621353782034 0"
        rpy="0 0 0" />
      <mass
        value="0.0133510458756028" />
      <inertia
        ixx="1.40543198066055E-06"
        ixy="3.74302421644642E-23"
        ixz="3.25957326037322E-24"
        iyy="2.34986077904369E-06"
        iyz="-3.61176480528272E-23"
        izz="1.40543198066055E-06" />
    </inertial>
    <visual>
      <origin
        xyz="0 0 0"
        rpy="0 0 0" />
      <geometry>
        <mesh
          filename="package://car_model_t3/meshes/left_wheel.STL" />
      </geometry>
      <material
        name="">
        <color
          rgba="0.796078431372549 0.823529411764706 0.937254901960784 1" />
      </material>
    </visual>
    <collision>
      <origin
        xyz="0 0 0"
        rpy="0 0 0" />
      <geometry>
        <mesh
          filename="package://car_model_t3/meshes/left_wheel.STL" />
      </geometry>
    </collision>
  </link>
  <joint
    name="base_to_left"
    type="continuous">
    <origin
      xyz="0 0.0425 0.003"
      rpy="0 0 0" />
    <parent
      link="base_link" />
    <child
      link="left_wheel" />
    <axis
      xyz="0 -1 0" />
    <safety_controller
      k_velocity="0" />
  </joint>
  <link
    name="right_wheel">
    <inertial>
      <origin
        xyz="0 0.00033062976853792 -2.77555756156289E-17"
        rpy="0 0 0" />
      <mass
        value="0.0134528334775791" />
      <inertia
        ixx="1.41844953412818E-06"
        ixy="-3.67641777769333E-23"
        ixz="-1.10140759586958E-23"
        iyy="2.36635037056385E-06"
        iyz="-3.80019189206278E-23"
        izz="1.41844953412819E-06" />
    </inertial>
    <visual>
      <origin
        xyz="0 0 0"
        rpy="0 0 0" />
      <geometry>
        <mesh
          filename="package://car_model_t3/meshes/right_wheel.STL" />
      </geometry>
      <material
        name="">
        <color
          rgba="0.796078431372549 0.823529411764706 0.937254901960784 1" />
      </material>
    </visual>
    <collision>
      <origin
        xyz="0 0 0"
        rpy="0 0 0" />
      <geometry>
        <mesh
          filename="package://car_model_t3/meshes/right_wheel.STL" />
      </geometry>
    </collision>
  </link>
  <joint
    name="base_to_right"
    type="continuous">
    <origin
      xyz="0 -0.0425 0.003"
      rpy="0 0 0" />
    <parent
      link="base_link" />
    <child
      link="right_wheel" />
    <axis
      xyz="0 -1 0" />
    <safety_controller
      k_velocity="0" />
  </joint>
  <link
    name="front_wheel">
    <inertial>
      <origin
        xyz="0 8.67361737988404E-19 0"
        rpy="0 0 0" />
      <mass
        value="0.00059040858425101" />
      <inertia
        ixx="7.87484011915424E-09"
        ixy="2.96957093606017E-24"
        ixz="-2.11386849513913E-26"
        iyy="1.42427926298594E-08"
        iyz="-2.68391875529742E-25"
        izz="7.87484011915423E-09" />
    </inertial>
    <visual>
      <origin
        xyz="0 0 0"
        rpy="0 0 0" />
      <geometry>
        <mesh
          filename="package://car_model_t3/meshes/front_wheel.STL" />
      </geometry>
      <material
        name="">
        <color
          rgba="0.411764705882353 0.411764705882353 0.411764705882353 1" />
      </material>
    </visual>
    <collision>
      <origin
        xyz="0 0 0"
        rpy="0 0 0" />
      <geometry>
        <mesh
          filename="package://car_model_t3/meshes/front_wheel.STL" />
      </geometry>
    </collision>
  </link>
  <joint
    name="base_to_front"
    type="continuous">
    <origin
      xyz="0.0585 0 -0.008"
      rpy="0 0 0" />
    <parent
      link="base_link" />
    <child
      link="front_wheel" />
    <axis
      xyz="0 -1 0" />
    <safety_controller
      k_velocity="0" />
  </joint>
  <link
    name="back_wheel">
    <inertial>
      <origin
        xyz="0 0 0"
        rpy="0 0 0" />
      <mass
        value="0.00059040858425101" />
      <inertia
        ixx="7.87484011915423E-09"
        ixy="-1.00689005131593E-24"
        ixz="-3.54301329761112E-24"
        iyy="1.42427926298594E-08"
        iyz="1.34565641763583E-25"
        izz="7.87484011915424E-09" />
    </inertial>
    <visual>
      <origin
        xyz="0 0 0"
        rpy="0 0 0" />
      <geometry>
        <mesh
          filename="package://car_model_t3/meshes/back_wheel.STL" />
      </geometry>
      <material
        name="">
        <color
          rgba="0.411764705882353 0.411764705882353 0.411764705882353 1" />
      </material>
    </visual>
    <collision>
      <origin
        xyz="0 0 0"
        rpy="0 0 0" />
      <geometry>
        <mesh
          filename="package://car_model_t3/meshes/back_wheel.STL" />
      </geometry>
    </collision>
  </link>
  <joint
    name="base_to_back"
    type="continuous">
    <origin
      xyz="-0.0715 0 -0.008"
      rpy="0 0 0" />
    <parent
      link="base_link" />
    <child
      link="back_wheel" />
    <axis
      xyz="0 -1 0" />
    <safety_controller
      k_velocity="0" />
  </joint>
</robot>